Workbook

Sheet Resumo
A2: Biblioteca de referências de UI | Pinterest
A4: Imagens distintas | B4: =COUNTA(Referencias!A2:A24523) -> 11236 | D4: Como usar
A5: Meta | B5: 10000 | D5: 1. Abra Referencias e filtre a macroárea.
A6: Progresso | B6: =B4/B5 -> 1.1236 | D6: 2. Abra o link da imagem ou da fonte.
A7: Pins com link individual | B7: 566 | D7: 3. Marque Sua seleção e Favorito.
A8: Páginas de origem | B8: 793 | D8: Categorias inferidas pelo contexto da fonte.
A9: Situação | B9: Coleta encerrada; imagens sendo enviadas ao GitHub | D9: A base ainda não recebeu curadoria visual.
D10: Imagem distinta não significa projeto distinto.
A12: Macroárea | B12: Imagens distintas | D12: =HYPERLINK("https://github.com/C-Icaro/ui-references-pinterest","Repositório privado: base e imagens") -> #ERROR!
A13: Alimentação e Delivery | B13: =COUNTIF(Referencias!B2:B24523,A13) -> 504
A14: Autenticação e Onboarding | B14: =COUNTIF(Referencias!B2:B24523,A14) -> 460
A15: CRM | B15: =COUNTIF(Referencias!B2:B24523,A15) -> 496
A16: Componentes | B16: =COUNTIF(Referencias!B2:B24523,A16) -> 561
A17: Dashboards e Analytics | B17: =COUNTIF(Referencias!B2:B24523,A17) -> 491
A18: E-commerce | B18: =COUNTIF(Referencias!B2:B24523,A18) -> 518
A19: Educação | B19: =COUNTIF(Referencias!B2:B24523,A19) -> 522
A20: Fintech e Bancos | B20: =COUNTIF(Referencias!B2:B24523,A20) -> 507
A21: IA e Chatbots | B21: =COUNTIF(Referencias!B2:B24523,A21) -> 161
A22: Landing Pages e Sites | B22: =COUNTIF(Referencias!B2:B24523,A22) -> 592
A23: Mapas e Mobilidade | B23: =COUNTIF(Referencias!B2:B24523,A23) -> 490
A24: Mobile | B24: =COUNTIF(Referencias!B2:B24523,A24) -> 567
A25: Mídia e Entretenimento | B25: =COUNTIF(Referencias!B2:B24523,A25) -> 516
A26: Produtividade e Gestão | B26: =COUNTIF(Referencias!B2:B24523,A26) -> 490
A27: Redes Sociais e Comunidades | B27: =COUNTIF(Referencias!B2:B24523,A27) -> 497
A28: Saúde e Bem-estar | B28: =COUNTIF(Referencias!B2:B24523,A28) -> 516
A29: Tipografia e Cores | B29: =COUNTIF(Referencias!B2:B24523,A29) -> 502
A30: UI 3D | B30: =COUNTIF(Referencias!B2:B24523,A30) -> 487
A31: UI e UX Geral | B31: =COUNTIF(Referencias!B2:B24523,A31) -> 1849
A32: Viagens e Reservas | B32: =COUNTIF(Referencias!B2:B24523,A32) -> 510

Sheet Referencias
A1: ID | B1: Macroárea | C1: Subcategoria | D1: Título disponível | E1: Link do pin | F1: Link da imagem | G1: Página de origem | H1: Nome da fonte | I1: Tipo de captura | J1: Revisão visual | K1: Coletado em (UTC) | L1: Assinatura da imagem | M1: Sua seleção | N1: Favorito | O1: Suas notas
A2: UI-00001 | B2: Alimentação e Delivery | C2: app design inspiration for food apps | D2: Título não exposto pela fonte | F2: https://i.pinimg.com/originals/c3/2b/31/c32b3179b9bce2fb4a85fbb5b63e9777.jpg | G2: https://www.pinterest.com/ideas/app-design-inspiration-for-food-apps/921185940841/ | H2: App Design Inspiration for Food Apps | I2: Página pública: imagem vinculada à coletânea/tópico | J2: Não revisado visualmente; categoria inferida pela fonte | K2: 2026-10-23T02:08:14Z | L2: c32b3179b9bce2fb4a85fbb5b63e9777 | M2: A avaliar | N2: Não
A3: UI-00002 | B3: Alimentação e Delivery | C3: app design inspiration for food apps | D3: Título não exposto pela fonte | F3: https://i.pinimg.com/originals/c7/2f/fe/c72ffe4adfede523cfef9fae2e66e164.jpg | G3: https://www.pinterest.com/ideas/app-design-inspiration-for-food-apps/921185940841/ | H3: App Design Inspiration for Food Apps | I3: Página pública: imagem vinculada à coletânea/tópico | J3: Não revisado visualmente; categoria inferida pela fonte | K3: 2026-10-23T02:08:14Z | L3: c72ffe4adfede523cfef9fae2e66e164 | M3: A avaliar | N3: Não
A4: UI-00003 | B4: Alimentação e Delivery | C4: app design inspiration for food apps | D4: Título não exposto pela fonte | F4: https://i.pinimg.com/originals/d1/43/85/d1438560d90258e612498699d8cbaeaa.gif | G4: https://www.pinterest.com/ideas/app-design-inspiration-for-food-apps/921185940841/ | H4: App Design Inspiration for Food Apps | I4: Página pública: imagem vinculada à coletânea/tópico | J4: Não revisado visualmente; categoria inferida pela fonte | K4: 2026-10-23T02:08:14Z | L4: d1438560d90258e612498699d8cbaeaa | M4: A avaliar | N4: Não
A5: UI-00004 | B5: Alimentação e Delivery | C5: app design inspiration for food apps | D5: Título não exposto pela fonte | F5: https://i.pinimg.com/originals/e9/ff/00/e9ff00951125dd0fa845f546a3e7c946.jpg | G5: https://www.pinterest.com/ideas/app-design-inspiration-for-food-apps/921185940841/ | H5: App Design Inspiration for Food Apps | I5: Página pública: imagem vinculada à coletânea/tópico | J5: Não revisado visualmente; categoria inferida pela fonte | K5: 2026-10-23T02:08:14Z | L5: e9ff00951125dd0fa845f546a3e7c946 | M5: A avaliar | N5: Não
A6: UI-00005 | B6: Alimentação e Delivery | C6: app design inspiration for food apps | D6: Título não exposto pela fonte | F6: https://i.pinimg.com/originals/f9/63/e5/f963e5085a68e781e21ca5852bfa0ec5.jpg | G6: https://www.pinterest.com/ideas/app-design-inspiration-for-food-apps/921185940841/ | H6: App Design Inspiration for Food Apps | I6: Página pública: imagem vinculada à coletânea/tópico | J6: Não revisado visualmente; categoria inferida pela fonte | K6: 2026-10-23T02:08:14Z | L6: f963e5085a68e781e21ca5852bfa0ec5 | M6: A avaliar | N6: Não
A7: UI-00006 | B7: Alimentação e Delivery | C7: best food website design | D7: Título não exposto pela fonte | F7: https://i.pinimg.com/originals/06/4e/06/064e06b3a65c60075704c6a70405a088.jpg | G7: https://www.pinterest.com/ideas/best-food-website-design/937630932982/ | H7: Best Food Website Design | I7: Página pública: imagem vinculada à coletânea/tópico | J7: Não revisado visualmente; categoria inferida pela fonte | K7: 2026-10-23T02:06:07Z | L7: 064e06b3a65c60075704c6a70405a088 | M7: A avaliar | N7: Não
A8: UI-00007 | B8: Alimentação e Delivery | C8: best food website design | D8: Título não exposto pela fonte | F8: https://i.pinimg.com/originals/11/69/c9/1169c95c97a17869c89386890108832f.jpg | G8: https://www.pinterest.com/ideas/best-food-website-design/937630932982/ | H8: Best Food Website Design | I8: Página pública: imagem vinculada à coletânea/tópico | J8: Não revisado visualmente; categoria inferida pela fonte | K8: 2026-10-23T02:06:07Z | L8: 1169c95c97a17869c89386890108832f | M8: A avaliar | N8: Não
A9: UI-00008 | B9: Alimentação e Delivery | C9: best food website design | D9: Título não exposto pela fonte | F9: https://i.pinimg.com/originals/11/ff/cf/11ffcff027e910c23ff708e96a83cb28.jpg | G9: https://www.pinterest.com/ideas/best-food-website-design/937630932982/ | H9: Best Food Website Design | I9: Página pública: imagem vinculada à coletânea/tópico | J9: Não revisado visualmente; categoria inferida pela fonte | K9: 2026-10-23T02:06:07Z | L9: 11ffcff027e910c23ff708e96a83cb28 | M9: A avaliar | N9: Não
A10: UI-00009 | B10: Alimentação e Delivery | C10: best food website design | D10: Título não exposto pela fonte | F10: https://i.pinimg.com/originals/14/35/01/143501d883b65aec96727b9b9200856b.jpg | G10: https://www.pinterest.com/ideas/best-food-website-design/937630932982/ | H10: Best Food Website Design | I10: Página pública: imagem vinculada à coletânea/tópico | J10: Não revisado visualmente; categoria inferida pela fonte | K10: 2026-10-23T02:06:07Z | L10: 143501d883b65aec96727b9b9200856b | M10: A avaliar | N10: Não
A11: UI-00010 | B11: Alimentação e Delivery | C11: best food website design | D11: Título não exposto pela fonte | F11: https://i.pinimg.com/originals/1f/2e/48/1f2e48a58106faebbd24833a93fd121e.png | G11: https://www.pinterest.com/ideas/best-food-website-design/937630932982/ | H11: Best Food Website Design | I11: Página pública: imagem vinculada à coletânea/tópico | J11: Não revisado visualmente; categoria inferida pela fonte | K11: 2026-10-23T02:06:07Z | L11: 1f2e48a58106faebbd24833a93fd121e | M11: A avaliar | N11: Não
A12: UI-00011 | B12: Alimentação e Delivery | C12: best food website design | D12: Título não exposto pela fonte | F12: https://i.pinimg.com/originals/2d/b3/ab/2db3abf45da8929c0c6650d6177b7e8f.jpg | G12: https://www.pinterest.com/ideas/best-food-website-design/937630932982/ | H12: Best Food Website Design | I12: Página pública: imagem vinculada à coletânea/tópico | J12: Não revisado visualmente; categoria inferida pela fonte | K12: 2026-10-23T02:06:07Z | L12: 2db3abf45da8929c0c6650d6177b7e8f | M12: A avaliar | N12: Não
A13: UI-00012 | B13: Alimentação e Delivery | C13: best food website design | D13: Título não exposto pela fonte | F13: https://i.pinimg.com/originals/2f/c6/4f/2fc64fc35f98082134ddaff58624405f.jpg | G13: https://www.pinterest.com/ideas/best-food-website-design/937630932982/ | H13: Best Food Website Design | I13: Página pública: imagem vinculada à coletânea/tópico | J13: Não revisado visualmente; categoria inferida pela fonte | K13: 2026-10-23T02:06:07Z | L13: 2fc64fc35f98082134ddaff58624405f | M13: A avaliar | N13: Não
... A232: UI-00231 | B232: Alimentação e Delivery | C232: food company website design | D232: Título não exposto pela fonte | F232: https://i.pinimg.com/originals/db/e4/66/dbe466212d05ec71c04d561d4788cf8e.png | G232: https://www.pinterest.com/ideas/food-company-website-design/912251939332/ | H232: Food Company Website Design | I232: Página pública: imagem vinculada à coletânea/tópico | J232: Não revisado visualmente; categoria inferida pela fonte | K232: 2026-10-23T02:06:25Z | L232: dbe466212d05ec71c04d561d4788cf8e | M232: A avaliar | N232: Não
A233: UI-00232 | B233: Alimentação e Delivery | C233: Food Ordering App Design | D233: Título não exposto pela fonte | F233: https://i.pinimg.com/originals/04/b9/0d/04b90d943870318058fb0db958930b72.jpg | G233: https://www.pinterest.com/PixelFlowUI/food-ordering-app-design/ | I233: Página pública: imagem vinculada à coletânea/tópico | J233: Não revisado visualmente; categoria inferida pela fonte | K233: 2026-10-23T02:07:06Z | L233: 04b90d943870318058fb0db958930b72 | M233: A avaliar | N233: Não
A234: UI-00233 | B234: Alimentação e Delivery | C234: Food Ordering App Design | D234: Título não exposto pela fonte | F234: https://i.pinimg.com/originals/0d/a0/30/0da030137c3a0940b15ac98f4b1887c4.png | G234: https://www.pinterest.com/PixelFlowUI/food-ordering-app-design/ | I234: Página pública: imagem vinculada à coletânea/tópico | J234: Não revisado visualmente; categoria inferida pela fonte | K234: 2026-10-23T02:07:06Z | L234: 0da030137c3a0940b15ac98f4b1887c4 | M234: A avaliar | N234: Não
A235: UI-00234 | B235: Alimentação e Delivery | C235: Food Ordering App Design | D235: Título não exposto pela fonte | F235: https://i.pinimg.com/originals/13/17/71/131771ab0a19a5caf39d6158b107f2aa.jpg | G235: https://www.pinterest.com/PixelFlowUI/food-ordering-app-design/ | I235: Página pública: imagem vinculada à coletânea/tópico | J235: Não revisado visualmente; categoria inferida pela fonte | K235: 2026-10-23T02:07:06Z | L235: 131771ab0a19a5caf39d6158b107f2aa | M235: A avaliar | N235: Não
A236: UI-00235 | B236: Alimentação e Delivery | C236: Food Ordering App Design | D236: Título não exposto pela fonte | F236: https://i.pinimg.com/originals/1b/a2/d2/1ba2d262cbe066c8ef0ff112ac3ce0c2.webp | G236: https://www.pinterest.com/PixelFlowUI/food-ordering-app-design/ | I236: Página pública: imagem vinculada à coletânea/tópico | J236: Não revisado visualmente; categoria inferida pela fonte | K236: 2026-10-23T02:07:06Z | L236: 1ba2d262cbe066c8ef0ff112ac3ce0c2 | M236: A avaliar | N236: Não
A237: UI-00236 | B237: Alimentação e Delivery | C237: Food Ordering App Design | D237: Título não exposto pela fonte | F237: https://i.pinimg.com/originals/39/09/40/390940e4416bb8e93b35fe5bbbadd1a4.jpg | G237: https://www.pinterest.com/PixelFlowUI/food-ordering-app-design/ | I237: Página pública: imagem vinculada à coletânea/tópico | J237: Não revisado visualmente; categoria inferida pela fonte | K237: 2026-10-23T02:07:06Z | L237: 390940e4416bb8e93b35fe5bbbadd1a4 | M237: A avaliar | N237: Não
A238: UI-00237 | B238: Alimentação e Delivery | C238: Food Ordering App Design | D238: Título não exposto pela fonte | F238: https://i.pinimg.com/originals/4b/16/1d/4b161d2b9dd39bffc6cc70808b74498e.jpg | G238: https://www.pinterest.com/PixelFlowUI/food-ordering-app-design/ | I238: Página pública: imagem vinculada à coletânea/tópico | J238: Não revisado visualmente; categoria inferida pela fonte | K238: 2026-10-23T02:07:06Z | L238: 4b161d2b9dd39bffc6cc70808b74498e | M238: A avaliar | N238: Não
A239: UI-00238 | B239: Alimentação e Delivery | C239: Food Ordering App Design | D239: Título não exposto pela fonte | F239: https://i.pinimg.com/originals/51/15/ee/5115ee8f41d25eedf3a16a467fb493b6.png | G239: https://www.pinterest.com/PixelFlowUI/food-ordering-app-design/ | I239: Página pública: imagem vinculada à coletânea/tópico | J239: Não revisado visualmente; categoria inferida pela fonte | K239: 2026-10-23T02:07:06Z | L239: 5115ee8f41d25eedf3a16a467fb493b6 | M239: A avaliar | N239: Não
A240: UI-00239 | B240: Alimentação e Delivery | C240: Food Ordering App Design | D240: Título não exposto pela fonte | F240: https://i.pinimg.com/originals/54/8b/4e/548b4e6c37a70fc1b2015d98b883a096.jpg | G240: https://www.pinterest.com/PixelFlowUI/food-ordering-app-design/ | I240: Página pública: imagem vinculada à coletânea/tópico | J240: Não revisado visualmente; categoria inferida pela fonte | K240: 2026-10-23T02:07:06Z | L240: 548b4e6c37a70fc1b2015d98b883a096 | M240: A avaliar | N240: Não
A241: UI-00240 | B241: Alimentação e Delivery | C241: Food Ordering App Design | D241: Título não exposto pela fonte | F241: https://i.pinimg.com/originals/69/04/07/6904071a5155e9d1126389c3614409ef.png | G241: https://www.pinterest.com/PixelFlowUI/food-ordering-app-design/ | I241: Página pública: imagem vinculada à coletânea/tópico | J241: Não revisado visualmente; categoria inferida pela fonte | K241: 2026-10-23T02:07:06Z | L241: 6904071a5155e9d1126389c3614409ef | M241: A avaliar | N241: Não
A242: UI-00241 | B242: Alimentação e Delivery | C242: Food Ordering App Design | D242: Título não exposto pela fonte | F242: https://i.pinimg.com/originals/69/bb/51/69bb511e1d0f58e14b563752441bd656.jpg | G242: https://www.pinterest.com/PixelFlowUI/food-ordering-app-design/ | I242: Página pública: imagem vinculada à coletânea/tópico | J242: Não revisado visualmente; categoria inferida pela fonte | K242: 2026-10-23T02:07:06Z | L242: 69bb511e1d0f58e14b563752441bd656 | M242: A avaliar | N242: Não
A243: UI-00242 | B243: Alimentação e Delivery | C243: Food Ordering App Design | D243: Título não exposto pela fonte | F243: https://i.pinimg.com/originals/69/fe/51/69fe51dd6778af6fd5859af92e0552c9.jpg | G243: https://www.pinterest.com/PixelFlowUI/food-ordering-app-design/ | I243: Página pública: imagem vinculada à coletânea/tópico | J243: Não revisado visualmente; categoria inferida pela fonte | K243: 2026-10-23T02:07:06Z | L243: 69fe51dd6778af6fd5859af92e0552c9 | M243: A avaliar | N243: Não
A244: UI-00243 | B244: Alimentação e Delivery | C244: Food Ordering App Design | D244: Título não exposto pela fonte | F244: https://i.pinimg.com/originals/79/27/5f/79275ffe9a1969c8963572c250c73f63.gif | G244: https://www.pinterest.com/PixelFlowUI/food-ordering-app-design/ | I244: Página pública: imagem vinculada à coletânea/tópico | J244: Não revisado visualmente; categoria inferida pela fonte | K244: 2026-10-23T02:07:06Z | L244: 79275ffe9a1969c8963572c250c73f63 | M244: A avaliar | N244: Não
... A257: UI-00256 | B257: Alimentação e Delivery | C257: Food Ordering App Design | D257: Título não exposto pela fonte | F257: https://i.pinimg.com/originals/ed/bb/12/edbb122564a05d9f495930b10ce9ae25.jpg | G257: https://www.pinterest.com/PixelFlowUI/food-ordering-app-design/ | I257: Página pública: imagem vinculada à coletânea/tópico | J257: Não revisado visualmente; categoria inferida pela fonte | K257: 2026-10-23T02:07:06Z | L257: edbb122564a05d9f495930b10ce9ae25 | M257: A avaliar | N257: Não
A258: UI-00257 | B258: Autenticação e Onboarding | C258: 3. LOGIN SCREEN | D258: Título não exposto pela fonte | F258: https://i.pinimg.com/originals/05/96/35/0596355f9811e768d0a588df299eca8a.png | G258: https://www.pinterest.com/dineshnayakdn369/3-login-screen/ | H258: 50 3. LOGIN SCREEN ideas in 2026 | mobile login, app login, login screen mobile ui | I258: Página pública: imagem vinculada à coletânea/tópico | J258: Não revisado visualmente; categoria inferida pela fonte | K258: 2026-10-23T02:06:42Z | L258: 0596355f9811e768d0a588df299eca8a | M258: A avaliar | N258: Não
A259: UI-00258 | B259: Autenticação e Onboarding | C259: 3. LOGIN SCREEN | D259: Título não exposto pela fonte | F259: https://i.pinimg.com/originals/11/e3/cd/11e3cd9bf63f42048f55a5889872d7fb.jpg | G259: https://www.pinterest.com/dineshnayakdn369/3-login-screen/ | H259: 50 3. LOGIN SCREEN ideas in 2026 | mobile login, app login, login screen mobile ui | I259: Página pública: imagem vinculada à coletânea/tópico | J259: Não revisado visualmente; categoria inferida pela fonte | K259: 2026-10-23T02:06:42Z | L259: 11e3cd9bf63f42048f55a5889872d7fb | M259: A avaliar | N259: Não
A260: UI-00259 | B260: Autenticação e Onboarding | C260: 3. LOGIN SCREEN | D260: Título não exposto pela fonte | F260: https://i.pinimg.com/originals/1d/65/ee/1d65ee0d32c33fbb138409004bd53baf.jpg | G260: https://www.pinterest.com/dineshnayakdn369/3-login-screen/ | H260: 50 3. LOGIN SCREEN ideas in 2026 | mobile login, app login, login screen mobile ui | I260: Página pública: imagem vinculada à coletânea/tópico | J260: Não revisado visualmente; categoria inferida pela fonte | K260: 2026-10-23T02:06:42Z | L260: 1d65ee0d32c33fbb138409004bd53baf | M260: A avaliar | N260: Não
A261: UI-00260 | B261: Autenticação e Onboarding | C261: 3. LOGIN SCREEN | D261: Título não exposto pela fonte | F261: https://i.pinimg.com/originals/22/21/07/2221076fb989c0bb412d40d01a5791dc.jpg | G261: https://www.pinterest.com/dineshnayakdn369/3-login-screen/ | H261: 50 3. LOGIN SCREEN ideas in 2026 | mobile login, app login, login screen mobile ui | I261: Página pública: imagem vinculada à coletânea/tópico | J261: Não revisado visualmente; categoria inferida pela fonte | K261: 2026-10-23T02:06:42Z | L261: 2221076fb989c0bb412d40d01a5791dc | M261: A avaliar | N261: Não
A262: UI-00261 | B262: Autenticação e Onboarding | C262: 3. LOGIN SCREEN | D262: Título não exposto pela fonte | F262: https://i.pinimg.com/originals/29/30/d6/2930d68c7da54629a7894ccb1149962f.png | G262: https://www.pinterest.com/dineshnayakdn369/3-login-screen/ | H262: 50 3. LOGIN SCREEN ideas in 2026 | mobile login, app login, login screen mobile ui | I262: Página pública: imagem vinculada à coletânea/tópico | J262: Não revisado visualmente; categoria inferida pela fonte | K262: 2026-10-23T02:06:42Z | L262: 2930d68c7da54629a7894ccb1149962f | M262: A avaliar | N262: Não
A263: UI-00262 | B263: Autenticação e Onboarding | C263: 3. LOGIN SCREEN | D263: Título não exposto pela fonte | F263: https://i.pinimg.com/originals/52/70/fe/5270fe6a7d099090690f12aeba20394b.jpg | G263: https://www.pinterest.com/dineshnayakdn369/3-login-screen/ | H263: 50 3. LOGIN SCREEN ideas in 2026 | mobile login, app login, login screen mobile ui | I263: Página pública: imagem vinculada à coletânea/tópico | J263: Não revisado visualmente; categoria inferida pela fonte | K263: 2026-10-23T02:06:42Z | L263: 5270fe6a7d099090690f12aeba20394b | M263: A avaliar | N263: Não
A264: UI-00263 | B264: Autenticação e Onboarding | C264: 3. LOGIN SCREEN | D264: Título não exposto pela fonte | F264: https://i.pinimg.com/originals/60/bb/b2/60bbb2da81fe0970ed012c9515a4133c.png | G264: https://www.pinterest.com/dineshnayakdn369/3-login-screen/ | H264: 50 3. LOGIN SCREEN ideas in 2026 | mobile login, app login, login screen mobile ui | I264: Página pública: imagem vinculada à coletânea/tópico | J264: Não revisado visualmente; categoria inferida pela fonte | K264: 2026-10-23T02:06:42Z | L264: 60bbb2da81fe0970ed012c9515a4133c | M264: A avaliar | N264: Não
A265: UI-00264 | B265: Autenticação e Onboarding | C265: 3. LOGIN SCREEN | D265: Título não exposto pela fonte | F265: https://i.pinimg.com/originals/6a/a0/f9/6aa0f98acf3beee79e6d107b98bafcac.jpg | G265: https://www.pinterest.com/dineshnayakdn369/3-login-screen/ | H265: 50 3. LOGIN SCREEN ideas in 2026 | mobile login, app login, login screen mobile ui | I265: Página pública: imagem vinculada à coletânea/tópico | J265: Não revisado visualmente; categoria inferida pela fonte | K265: 2026-10-23T02:06:42Z | L265: 6aa0f98acf3beee79e6d107b98bafcac | M265: A avaliar | N265: Não
A266: UI-00265 | B266: Autenticação e Onboarding | C266: 3. LOGIN SCREEN | D266: Título não exposto pela fonte | F266: https://i.pinimg.com/originals/71/dd/e0/71dde040554100f8b559ca49a651f21e.jpg | G266: https://www.pinterest.com/dineshnayakdn369/3-login-screen/ | H266: 50 3. LOGIN SCREEN ideas in 2026 | mobile login, app login, login screen mobile ui | I266: Página pública: imagem vinculada à coletânea/tópico | J266: Não revisado visualmente; categoria inferida pela fonte | K266: 2026-10-23T02:06:42Z | L266: 71dde040554100f8b559ca49a651f21e | M266: A avaliar | N266: Não
A267: UI-00266 | B267: Autenticação e Onboarding | C267: 3. LOGIN SCREEN | D267: Título não exposto pela fonte | F267: https://i.pinimg.com/originals/80/8d/ec/808decf210429b2ce48bcd866ba93a86.png | G267: https://www.pinterest.com/dineshnayakdn369/3-login-screen/ | H267: 50 3. LOGIN SCREEN ideas in 2026 | mobile login, app login, login screen mobile ui | I267: Página pública: imagem vinculada à coletânea/tópico | J267: Não revisado visualmente; categoria inferida pela fonte | K267: 2026-10-23T02:06:42Z | L267: 808decf210429b2ce48bcd866ba93a86 | M267: A avaliar | N267: Não
A268: UI-00267 | B268: Autenticação e Onboarding | C268: 3. LOGIN SCREEN | D268: Título não exposto pela fonte | F268: https://i.pinimg.com/originals/8a/ec/63/8aec6320f8f469668b0d7927edda128e.png | G268: https://www.pinterest.com/dineshnayakdn369/3-login-screen/ | H268: 50 3. LOGIN SCREEN ideas in 2026 | mobile login, app login, login screen mobile ui | I268: Página pública: imagem vinculada à coletânea/tópico | J268: Não revisado visualmente; categoria inferida pela fonte | K268: 2026-10-23T02:06:42Z | L268: 8aec6320f8f469668b0d7927edda128e | M268: A avaliar | N268: Não
A269: UI-00268 | B269: Autenticação e Onboarding | C269: 3. LOGIN SCREEN | D269: Título não exposto pela fonte | F269: https://i.pinimg.com/originals/91/00/92/910092394bb9d5f2a97d9ad367eb5131.jpg | G269: https://www.pinterest.com/dineshnayakdn369/3-login-screen/ | H269: 50 3. LOGIN SCREEN ideas in 2026 | mobile login, app login, login screen mobile ui | I269: Página pública: imagem vinculada à coletânea/tópico | J269: Não revisado visualmente; categoria inferida pela fonte | K269: 2026-10-23T02:06:42Z | L269: 910092394bb9d5f2a97d9ad367eb5131 | M269: A avaliar | N269: Não
... A405: UI-00404 | B405: UI e UX Geral | C405: designing app interface templates | D405: Título não exposto pela fonte | F405: https://i.pinimg.com/originals/e5/9b/4c/e59b4c64be8132106887c4068404b3f5.png | G405: https://www.pinterest.com/ideas/designing-app-interface-templates/954243316024/ | H405: Designing App Interface Templates | I405: Página pública: imagem vinculada à coletânea/tópico | J405: Não revisado visualmente; categoria inferida pela fonte | K405: 2026-10-23T02:06:11Z | L405: e59b4c64be8132106887c4068404b3f5 | M405: A avaliar | N405: Não
...

Sheet Fontes
A1: Página de origem | B1: Nome da fonte | C1: Imagens na base | D1: Tipo
A2: https://www.pinterest.com/ideas/app-design-inspiration-for-food-apps/921185940841/ | B2: App Design Inspiration for Food Apps | C2: 5 | D2: Tópico
A3: https://www.pinterest.com/ideas/best-food-website-design/937630932982/ | B3: Best Food Website Design | C3: 20 | D3: Tópico
A4: https://www.pinterest.com/ideas/best-restaurant-website-design/929252294751/ | B4: Best Restaurant Website Design | C4: 11 | D4: Tópico
A5: https://www.pinterest.com/ideas/colorful-food-app-design/915937352116/ | B5: Colorful Food App Design | C5: 10 | D5: Tópico
A6: https://www.pinterest.com/ideas/creating-food-app-interfaces/956412553240/ | B6: Creating Food App Interfaces | C6: 17 | D6: Tópico
A7: https://www.pinterest.com/ideas/creative-food-website-design/904312477709/ | B7: Creative Food Website Design | C7: 12 | D7: Tópico
A8: https://www.pinterest.com/ideas/creative-food-website-ideas/939320384784/ | B8: Creative Food Website Ideas | C8: 10 | D8: Tópico
A9: https://www.pinterest.com/ideas/delivery-app-dashboard/917833103396/ | B9: Delivery App Dashboard | C9: 18 | D9: Tópico
A10: https://www.pinterest.com/ideas/delivery-app-design/894926856672/ | B10: Delivery App Design | C10: 7 | D10: Tópico
A11: https://www.pinterest.com/ideas/delivery-app-interface-screens/902145139687/ | B11: Delivery App Interface Screens | C11: 16 | D11: Tópico
A12: https://www.pinterest.com/ideas/dog-food-website-design/900426060729/ | B12: Dog Food Website Design | C12: 20 | D12: Tópico
A13: https://www.pinterest.com/ideas/elegant-food-website-design/944812605727/ | B13: Elegant Food Website Design | C13: 15 | D13: Tópico
... A18: https://www.pinterest.com/ideas/food-company-website-design/912251939332/ | B18: Food Company Website Design | C18: 16 | D18: Tópico
A19: https://www.pinterest.com/PixelFlowUI/food-ordering-app-design/ | C19: 25 | D19: Coletânea
A20: https://www.pinterest.com/dineshnayakdn369/3-login-screen/ | B20: 50 3. LOGIN SCREEN ideas in 2026 | mobile login, app login, login screen mobile ui | C20: 20 | D20: Coletânea
A21: https://www.pinterest.com/ideas/android-app-login-page-design/898852656520/ | B21: Android App Login Page Design | C21: 13 | D21: Tópico
A22: https://www.pinterest.com/ideas/android-login-screen/918503989029/ | B22: Android Login Screen | C22: 9 | D22: Tópico
A23: https://www.pinterest.com/ideas/android-login-ui-design/913184501673/ | B23: Android Login Ui Design | C23: 2 | D23: Tópico
A24: https://www.pinterest.com/ideas/app-design-interface/943262663655/ | B24: App Design Interface | C24: 14 | D24: Tópico
A25: https://www.pinterest.com/ideas/app-login/952290929787/ | B25: App Login | C25: 20 | D25: Tópico
A26: https://www.pinterest.com/ideas/app-login-and-register-screen/959148603178/ | B26: App Login and Register Screen | C26: 14 | D26: Tópico
A27: https://www.pinterest.com/ideas/app-login-background/915526972241/ | B27: App Login Background | C27: 18 | D27: Tópico
A28: https://www.pinterest.com/ideas/app-login-design/951776222250/ | B28: App Login Design | C28: 3 | D28: Tópico
A29: https://www.pinterest.com/ideas/app-login-interface-design/953046347611/ | B29: App Login Interface Design | C29: 8 | D29: Tópico
A30: https://www.pinterest.com/ideas/app-login-screen-design-png/931560937187/ | B30: App Login Screen Design Png | C30: 16 | D30: Tópico
A31: https://www.pinterest.com/ideas/designing-app-interface-templates/954243316024/ | B31: Designing App Interface Templates | C31: 11 | D31: Tópico
A32: https://www.pinterest.com/Modern_UI_Library/login-design-ui-app/ | C32: 25 | D32: Coletânea
A33: https://www.pinterest.com/Modern_UI_Library/login-design-ui-mobile/ | C33: 23 | D33: Coletânea
A34: https://www.pinterest.com/Modern_UI_Library/login-design-ui-website/ | C34: 25 | D34: Coletânea
A35: https://www.pinterest.com/ideas/ui-design-interface-templates/910878231785/ | B35: Ui Design Interface Templates | C35: 16 | D35: Tópico
A36: https://www.pinterest.com/ideas/app-tab-bar-interface/961291322029/ | B36: App Tab Bar Interface | C36: 19 | D36: Tópico
A37: https://www.pinterest.com/ideas/blog-card-ui-design/941570922366/ | B37: Blog Card Ui Design | C37: 16 | D37: Tópico
A38: https://www.pinterest.com/ideas/bottom-navigation-bar-component-pack/953362098637/ | B38: Bottom Navigation Bar Component Pack | C38: 16 | D38: Tópico
A39: https://www.pinterest.com/ideas/card-ui-design/897179348952/ | B39: Card Ui Design | C39: 20 | D39: Tópico
A40: https://www.pinterest.com/ideas/card-ui-design-mobile/913640190578/ | B40: Card Ui Design Mobile | C40: 15 | D40: Tópico
A41: https://www.pinterest.com/Crafted_Interfaces_UI/figma-ui-kits-and-wordpress-themes/ | C41: 24 | D41: Coletânea
A42: https://www.pinterest.com/DesignResourcesLibrary/sketch-ui-kits/ | C42: 25 | D42: Coletânea
A43: https://www.pinterest.com/componentsinterface/ui-kit-design-website/ | B43: 900+ UI Kit Design Website ideas in 2026 | user interface design, dashboard ui, mobile app ui | C43: 23 | D43: Coletânea
A44: https://www.pinterest.com/figma_flow_ux/ui-kit-in-figma/ | B44: 900+ UI kit in figma ideas in 2026 | wireframe kit, ux kits, figma plugins free | C44: 23 | D44: Coletânea
...

Sheet Metodo
A1: Critério | B1: Aplicação
A2: Unidade de referência | B2: Uma imagem distinta publicada no Pinterest, deduplicada por assinatura do arquivo.
A3: Macroáreas | B3: UI 3D, Componentes e CRM como ponto de partida; temática ampliada por domínio e padrão de interface.
A4: Classificação | B4: Automática pelo nome da coletânea, tópico ou consulta. Não equivale a revisão individual da imagem.
A5: Links de pins | B5: Preenchidos somente quando expostos pela interface. Não foram reconstruídos a partir de IDs opacos.
A6: Imagens e origem | B6: Cada registro inclui URL da imagem e a página pública ou busca que a apresentou.
A7: Títulos ausentes | B7: O Pinterest omite títulos em parte das páginas públicas. Ausências são declaradas.
A8: Deduplicação | B8: Assinatura de 32 caracteres do arquivo de imagem; diferentes tamanhos do mesmo arquivo contam uma vez.
A9: Limite da deduplicação | B9: Recortes, edições e republicações com outro arquivo podem continuar presentes. Não foi feito teste de similaridade visual.
A10: Curadoria | B10: Nenhuma alegação de melhores interfaces, acessibilidade, usabilidade ou autoria foi validada individualmente.
A11: Data de consulta | B11: 22/10/2026, America/Sao_Paulo. Carimbos de coleta individuais em UTC.
A12: Referências iniciais | B12: https://br.pinterest.com/Icaro770/ui-3d/ | https://br.pinterest.com/Icaro770/componentes/ | https://br.pinterest.com/Icaro770/crm/
... A14: Acesso | B14: Planilha criada no Drive pessoal autorizado. Não foi solicitado compartilhamento público.
